Workbook
Name comp: '[1]unités constitutives SSIHT'!$C$2:$C$22

Sheet E5-FICHE SEMESTRE1 E5-IR
A1: BREVET DE TECHNICIEN SUPERIEUR CYBERSECURITE, INFORMATIQUE et RESEAUX, ELECTRONIQUE
A3: Épreuve E5 : Exploitation et maintenance de réseaux informatiques
A5: SESSION 2027
A7: Commentaire (obligatoire si note finale inférieure à 10/20) | C7: Académie : | E7: Académie de Versailles
C8: Établissement : | E8: Lycée Isaac Newton
C9: Nom : | E9: ABAID
C10: Prénom : | E10: Soulaimane
C11: Numéro du candidat : | E11: 2025001
C12: Date :
A14: GRILLE D'ÉVALUATION
C16: Positionner le niveau de maitrise
C17: Niveau 1 | D17: Niveau 2 | E17: Niveau 3 | F17: Niveau 4
A18: 0.2 | B18: C02 : ORGANISER UNE INTERVENTION | C18: Non réalisé | D18: Réalisation partielle | E18: Réalisation satisfaisante | F18: Réalisation très satisfaisante
A19: =SUM(A20:A24) | B19: Critères d’évaluation de la compétence | C19: 0 observable | D19: 1 observable | E19: 2 à 3 observables | F19: 4 observables
A20: 0.25 | B20: Les différents interlocuteurs et ressources sont identifiés | G20: =IF(C20="x",0,IF(D20="x",1,IF(E20="x",2,IF(F20="x",3,IF(TRUE,""))))) | H20: =COUNTBLANK(C20:F20) | I20: =IF(H20=3,"",IF(H20<>3,"EVALUATION DE CE CRITERE A REVOIR"))
A21: 0.25 | B21: Le cahier des charges préliminaire est complété et les ressources permettant de répondre au cahier des charges sont décrites | G21: =IF(C21="x",0,IF(D21="x",1,IF(E21="x",2,IF(F21="x",3,IF(TRUE,""))))) | H21: =COUNTBLANK(C21:F21) | I21: =IF(H21=3,"",IF(H21<>3,"EVALUATION DE CE CRITERE A REVOIR"))
A22: 0.2 | B22: Le planning prévisionnel est interprété | G22: =IF(C22="x",0,IF(D22="x",1,IF(E22="x",2,IF(F22="x",3,IF(TRUE,""))))) | H22: =COUNTBLANK(C22:F22) | I22: =IF(H22=3,"",IF(H22<>3,"EVALUATION DE CE CRITERE A REVOIR"))
A24: 0.3 | B24: - Face à un ensemble de faits, des actions appropriées à poser sont décidées - De façon à poser des actions au moment opportun dans un contexte déterminé, la prise en charge est adaptée selon les responsabilités - Le travail est préparé de façon à satisfaire les exigences de qualité, d’efficacité et d’échéancier | G24: =IF(C24="x",0,IF(D24="x",1,IF(E24="x",2,IF(F24="x",3,IF(TRUE,""))))) | H24: =COUNTBLANK(C24:F24) | I24: =IF(H24=3,"",IF(H24<>3,"EVALUATION DE CE CRITERE A REVOIR"))
E25: Total | F25: =SUMPRODUCT(A20:A24,G20:G24)
E26: Curseur | F26: =+F25
C27: Positionner le niveau de maitrise
C28: Niveau 1 | D28: Niveau 2 | E28: Niveau 3 | F28: Niveau 4
A29: 0.2 | B29: C06 : VALIDER UN SYSTÈME INFORMATIQUE | C29: Non réalisé | D29: Réalisation partielle | E29: Réalisation satisfaisante | F29: Réalisation très satisfaisante
A30: =SUM(A31:A37) | B30: Critères d’évaluation de la compétence | C30: 0 observable | D30: 1 observable | E30: 2 à 3 observables | F30: 4 observables
A31: 0.2 | B31: Les exigences à valider sont identifiées dans le périmètre défini | G31: =IF(C31="x",0,IF(D31="x",1,IF(E31="x",2,IF(F31="x",3,IF(TRUE,""))))) | H31: =COUNTBLANK(C31:F31) | I31: =IF(H31=3,"",IF(H31<>3,"EVALUATION DE CE CRITERE A REVOIR"))
A32: 0.2 | B32: Les procédures de test sont établies | G32: =IF(C32="x",0,IF(D32="x",1,IF(E32="x",2,IF(F32="x",3,IF(TRUE,""))))) | H32: =COUNTBLANK(C32:F32) | I32: =IF(H32=3,"",IF(H32<>3,"EVALUATION DE CE CRITERE A REVOIR"))
A33: 0.1 | B33: Les tests (unitaires, d’intégration et autres) sont appliqués | G33: =IF(C33="x",0,IF(D33="x",1,IF(E33="x",2,IF(F33="x",3,IF(TRUE,""))))) | H33: =COUNTBLANK(C33:F33) | I33: =IF(H33=3,"",IF(H33<>3,"EVALUATION DE CE CRITERE A REVOIR"))
A34: 0.1 | B34: Les résultats de tests sont synthétisés pour évaluer la conformité globale | G34: =IF(C34="x",0,IF(D34="x",1,IF(E34="x",2,IF(F34="x",3,IF(TRUE,""))))) | H34: =COUNTBLANK(C34:F34) | I34: =IF(H34=3,"",IF(H34<>3,"EVALUATION DE CE CRITERE A REVOIR"))
A35: 0.1 | B35: Le document de recette est validé par le client et la recette est réalisée avec le client | G35: =IF(C35="x",0,IF(D35="x",1,IF(E35="x",2,IF(F35="x",3,IF(TRUE,""))))) | H35: =COUNTBLANK(C35:F35) | I35: =IF(H35=3,"",IF(H35<>3,"EVALUATION DE CE CRITERE A REVOIR"))
A37: 0.3 | B37: - Le travail est préparé de façon à satisfaire les exigences de qualité, d’efficacité et d’échéancier - Le calme est conservé de façon constante dans des situations particulières, tout en persévérant dans la tâche jusqu’à l’atteinte du résultat sans se décourager - Face à un ensemble de faits, des actions appropriées à poser sont décidées | G37: =IF(C37="x",0,IF(D37="x",1,IF(E37="x",2,IF(F37="x",3,IF(TRUE,""))))) | H37: =COUNTBLANK(C37:F37) | I37: =IF(H37=3,"",IF(H37<>3,"EVALUATION DE CE CRITERE A REVOIR"))
E38: Total | F38: =SUMPRODUCT(A31:A37,G31:G37)
E39: Curseur | F39: =F38
C40: Positionner le niveau de maitrise
C41: Niveau 1 | D41: Niveau 2 | E41: Niveau 3 | F41: Niveau 4
A42: 0.3 | B42: C09 : INSTALLER UN RÉSEAU INFORMATIQUE | C42: Non réalisé | D42: Réalisation partielle | E42: Réalisation satisfaisante | F42: Réalisation très satisfaisante
A43: =SUM(A44:A50) | B43: Critères d’évaluation de la compétence | C43: 0 observable | D43: 1 observable | E43: 2 à 3 observables | F43: 4 observables
A44: 0.2 | B44: Les équipements nécessaires à la réponse au CDC (fourni par le client) sont identifiés | G44: =IF(C44="x",0,IF(D44="x",1,IF(E44="x",2,IF(F44="x",3,IF(TRUE,""))))) | H44: =COUNTBLANK(C44:F44) | I44: =IF(H44=3,"",IF(H44<>3,"EVALUATION DE CE CRITERE A REVOIR"))
A45: 0.2 | B45: Une procédure de configuration ou d’installation est déterminée ainsi que les points critiques, les procédures étant soumises à validation si nécessaire | G45: =IF(C45="x",0,IF(D45="x",1,IF(E45="x",2,IF(F45="x",3,IF(TRUE,""))))) | H45: =COUNTBLANK(C45:F45) | I45: =IF(H45=3,"",IF(H45<>3,"EVALUATION DE CE CRITERE A REVOIR"))
A46: 0.1 | B46: La ou les procédures choisies sont suivies | G46: =IF(C46="x",0,IF(D46="x",1,IF(E46="x",2,IF(F46="x",3,IF(TRUE,""))))) | H46: =COUNTBLANK(C46:F46) | I46: =IF(H46=3,"",IF(H46<>3,"EVALUATION DE CE CRITERE A REVOIR"))
A47: 0.1 | B47: Les activités sont menées en respectant les règles de sécurité | G47: =IF(C47="x",0,IF(D47="x",1,IF(E47="x",2,IF(F47="x",3,IF(TRUE,""))))) | H47: =COUNTBLANK(C47:F47) | I47: =IF(H47=3,"",IF(H47<>3,"EVALUATION DE CE CRITERE A REVOIR"))
...

Sheet E5-FICHE SEMESTRE2 E5-IR
A1: BREVET DE TECHNICIEN SUPERIEUR CYBERSECURITE, INFORMATIQUE et RESEAUX, ELECTRONIQUE
A3: Épreuve E5 : Exploitation et maintenance de réseaux informatiques
A5: SESSION 2027
A7: Commentaire (obligatoire si note finale inférieure à 10/20) | C7: Académie : | E7: Académie de Versailles
C8: Établissement : | E8: Lycée Isaac Newton
C9: Nom : | E9: ABAID
C10: Prénom : | E10: Soulaimane
C11: Numéro du candidat : | E11: 2025001
C12: Date :
A14: GRILLE D'ÉVALUATION
C16: Positionner le niveau de maitrise
C17: Niveau 1 | D17: Niveau 2 | E17: Niveau 3 | F17: Niveau 4
A18: 0.2 | B18: C02 : ORGANISER UNE INTERVENTION | C18: Non réalisé | D18: Réalisation partielle | E18: Réalisation satisfaisante | F18: Réalisation très satisfaisante
A19: =SUM(A20:A24) | B19: Critères d’évaluation de la compétence | C19: 0 observable | D19: 1 observable | E19: 2 à 3 observables | F19: 4 observables
A20: 0.25 | B20: Les différents interlocuteurs et ressources sont identifiés | G20: =IF(C20="x",0,IF(D20="x",1,IF(E20="x",2,IF(F20="x",3,IF(TRUE,""))))) | H20: =COUNTBLANK(C20:F20) | I20: =IF(H20=3,"",IF(H20<>3,"EVALUATION DE CE CRITERE A REVOIR"))
A21: 0.25 | B21: Le cahier des charges préliminaire est complété et les ressources permettant de répondre au cahier des charges sont décrites | G21: =IF(C21="x",0,IF(D21="x",1,IF(E21="x",2,IF(F21="x",3,IF(TRUE,""))))) | H21: =COUNTBLANK(C21:F21) | I21: =IF(H21=3,"",IF(H21<>3,"EVALUATION DE CE CRITERE A REVOIR"))
A22: 0.2 | B22: Le planning prévisionnel est interprété | G22: =IF(C22="x",0,IF(D22="x",1,IF(E22="x",2,IF(F22="x",3,IF(TRUE,""))))) | H22: =COUNTBLANK(C22:F22) | I22: =IF(H22=3,"",IF(H22<>3,"EVALUATION DE CE CRITERE A REVOIR"))
A24: 0.3 | B24: - Face à un ensemble de faits, des actions appropriées à poser sont décidées - De façon à poser des actions au moment opportun dans un contexte déterminé, la prise en charge est adaptée selon les responsabilités - Le travail est préparé de façon à satisfaire les exigences de qualité, d’efficacité et d’échéancier | G24: =IF(C24="x",0,IF(D24="x",1,IF(E24="x",2,IF(F24="x",3,IF(TRUE,""))))) | H24: =COUNTBLANK(C24:F24) | I24: =IF(H24=3,"",IF(H24<>3,"EVALUATION DE CE CRITERE A REVOIR"))
E25: Total | F25: =SUMPRODUCT(A20:A24,G20:G24)
E26: Curseur | F26: =MAX(F25,'E5-FICHE SEMESTRE1 E5-IR'!F25/2)
C27: Positionner le niveau de maitrise
C28: Niveau 1 | D28: Niveau 2 | E28: Niveau 3 | F28: Niveau 4
A29: 0.2 | B29: C06 : VALIDER UN SYSTÈME INFORMATIQUE | C29: Non réalisé | D29: Réalisation partielle | E29: Réalisation satisfaisante | F29: Réalisation très satisfaisante
A30: =SUM(A31:A37) | B30: Critères d’évaluation de la compétence | C30: 0 observable | D30: 1 observable | E30: 2 à 3 observables | F30: 4 observables
A31: 0.2 | B31: Les exigences à valider sont identifiées dans le périmètre défini | G31: =IF(C31="x",0,IF(D31="x",1,IF(E31="x",2,IF(F31="x",3,IF(TRUE,""))))) | H31: =COUNTBLANK(C31:F31) | I31: =IF(H31=3,"",IF(H31<>3,"EVALUATION DE CE CRITERE A REVOIR"))
A32: 0.2 | B32: Les procédures de test sont établies | G32: =IF(C32="x",0,IF(D32="x",1,IF(E32="x",2,IF(F32="x",3,IF(TRUE,""))))) | H32: =COUNTBLANK(C32:F32) | I32: =IF(H32=3,"",IF(H32<>3,"EVALUATION DE CE CRITERE A REVOIR"))
A33: 0.1 | B33: Les tests (unitaires, d’intégration et autres) sont appliqués | G33: =IF(C33="x",0,IF(D33="x",1,IF(E33="x",2,IF(F33="x",3,IF(TRUE,""))))) | H33: =COUNTBLANK(C33:F33) | I33: =IF(H33=3,"",IF(H33<>3,"EVALUATION DE CE CRITERE A REVOIR"))
A34: 0.1 | B34: Les résultats de tests sont synthétisés pour évaluer la conformité globale | G34: =IF(C34="x",0,IF(D34="x",1,IF(E34="x",2,IF(F34="x",3,IF(TRUE,""))))) | H34: =COUNTBLANK(C34:F34) | I34: =IF(H34=3,"",IF(H34<>3,"EVALUATION DE CE CRITERE A REVOIR"))
A35: 0.1 | B35: Le document de recette est validé par le client et la recette est réalisée avec le client | G35: =IF(C35="x",0,IF(D35="x",1,IF(E35="x",2,IF(F35="x",3,IF(TRUE,""))))) | H35: =COUNTBLANK(C35:F35) | I35: =IF(H35=3,"",IF(H35<>3,"EVALUATION DE CE CRITERE A REVOIR"))
A37: 0.3 | B37: - Le travail est préparé de façon à satisfaire les exigences de qualité, d’efficacité et d’échéancier - Le calme est conservé de façon constante dans des situations particulières, tout en persévérant dans la tâche jusqu’à l’atteinte du résultat sans se décourager - Face à un ensemble de faits, des actions appropriées à poser sont décidées | G37: =IF(C37="x",0,IF(D37="x",1,IF(E37="x",2,IF(F37="x",3,IF(TRUE,""))))) | H37: =COUNTBLANK(C37:F37) | I37: =IF(H37=3,"",IF(H37<>3,"EVALUATION DE CE CRITERE A REVOIR"))
E38: Total | F38: =SUMPRODUCT(A31:A37,G31:G37)
E39: Curseur | F39: =MAX(F38,'E5-FICHE SEMESTRE1 E5-IR'!F38/2)
C40: Positionner le niveau de maitrise
C41: Niveau 1 | D41: Niveau 2 | E41: Niveau 3 | F41: Niveau 4
A42: 0.3 | B42: C09 : INSTALLER UN RÉSEAU INFORMATIQUE | C42: Non réalisé | D42: Réalisation partielle | E42: Réalisation satisfaisante | F42: Réalisation très satisfaisante
A43: =SUM(A44:A50) | B43: Critères d’évaluation de la compétence | C43: 0 observable | D43: 1 observable | E43: 2 à 3 observables | F43: 4 observables
A44: 0.2 | B44: Les équipements nécessaires à la réponse au CDC (fourni par le client) sont identifiés | G44: =IF(C44="x",0,IF(D44="x",1,IF(E44="x",2,IF(F44="x",3,IF(TRUE,""))))) | H44: =COUNTBLANK(C44:F44) | I44: =IF(H44=3,"",IF(H44<>3,"EVALUATION DE CE CRITERE A REVOIR"))
A45: 0.2 | B45: Une procédure de configuration ou d’installation est déterminée ainsi que les points critiques, les procédures étant soumises à validation si nécessaire | G45: =IF(C45="x",0,IF(D45="x",1,IF(E45="x",2,IF(F45="x",3,IF(TRUE,""))))) | H45: =COUNTBLANK(C45:F45) | I45: =IF(H45=3,"",IF(H45<>3,"EVALUATION DE CE CRITERE A REVOIR"))
A46: 0.1 | B46: La ou les procédures choisies sont suivies | G46: =IF(C46="x",0,IF(D46="x",1,IF(E46="x",2,IF(F46="x",3,IF(TRUE,""))))) | H46: =COUNTBLANK(C46:F46) | I46: =IF(H46=3,"",IF(H46<>3,"EVALUATION DE CE CRITERE A REVOIR"))
A47: 0.1 | B47: Les activités sont menées en respectant les règles de sécurité | G47: =IF(C47="x",0,IF(D47="x",1,IF(E47="x",2,IF(F47="x",3,IF(TRUE,""))))) | H47: =COUNTBLANK(C47:F47) | I47: =IF(H47=3,"",IF(H47<>3,"EVALUATION DE CE CRITERE A REVOIR"))
...

Sheet E5-FICHE SEMESTRE3 E5-IR
A1: BREVET DE TECHNICIEN SUPERIEUR CYBERSECURITE, INFORMATIQUE et RESEAUX, ELECTRONIQUE
A3: Épreuve E5 : Exploitation et maintenance de réseaux informatiques
A5: SESSION 2027
A7: Commentaire (obligatoire si note finale inférieure à 10/20) | C7: Académie : | E7: Académie de Versailles
C8: Établissement : | E8: Lycée Isaac Newton
C9: Nom : | E9: ABAID
C10: Prénom : | E10: Soulaimane
C11: Numéro du candidat : | E11: 2025001
C12: Date :
A14: GRILLE D'ÉVALUATION
C16: Positionner le niveau de maitrise
C17: Niveau 1 | D17: Niveau 2 | E17: Niveau 3 | F17: Niveau 4
A18: 0.2 | B18: C02 : ORGANISER UNE INTERVENTION | C18: Non réalisé | D18: Réalisation partielle | E18: Réalisation satisfaisante | F18: Réalisation très satisfaisante
A19: =SUM(A20:A24) | B19: Critères d’évaluation de la compétence | C19: 0 observable | D19: 1 observable | E19: 2 à 3 observables | F19: 4 observables
A20: 0.25 | B20: Les différents interlocuteurs et ressources sont identifiés | G20: =IF(C20="x",0,IF(D20="x",1,IF(E20="x",2,IF(F20="x",3,IF(TRUE,""))))) | H20: =COUNTBLANK(C20:F20) | I20: =IF(H20=3,"",IF(H20<>3,"EVALUATION DE CE CRITERE A REVOIR"))
A21: 0.25 | B21: Le cahier des charges préliminaire est complété et les ressources permettant de répondre au cahier des charges sont décrites | G21: =IF(C21="x",0,IF(D21="x",1,IF(E21="x",2,IF(F21="x",3,IF(TRUE,""))))) | H21: =COUNTBLANK(C21:F21) | I21: =IF(H21=3,"",IF(H21<>3,"EVALUATION DE CE CRITERE A REVOIR"))
A22: 0.2 | B22: Le planning prévisionnel est interprété | G22: =IF(C22="x",0,IF(D22="x",1,IF(E22="x",2,IF(F22="x",3,IF(TRUE,""))))) | H22: =COUNTBLANK(C22:F22) | I22: =IF(H22=3,"",IF(H22<>3,"EVALUATION DE CE CRITERE A REVOIR"))
A24: 0.3 | B24: - Face à un ensemble de faits, des actions appropriées à poser sont décidées - De façon à poser des actions au moment opportun dans un contexte déterminé, la prise en charge est adaptée selon les responsabilités - Le travail est préparé de façon à satisfaire les exigences de qualité, d’efficacité et d’échéancier | G24: =IF(C24="x",0,IF(D24="x",1,IF(E24="x",2,IF(F24="x",3,IF(TRUE,""))))) | H24: =COUNTBLANK(C24:F24) | I24: =IF(H24=3,"",IF(H24<>3,"EVALUATION DE CE CRITERE A REVOIR"))
E25: Total | F25: =SUMPRODUCT(A20:A24,G20:G24)
E26: Curseur | F26: =MAX(F25,'E5-FICHE SEMESTRE2 E5-IR'!F26*2/3)
C27: Positionner le niveau de maitrise
C28: Niveau 1 | D28: Niveau 2 | E28: Niveau 3 | F28: Niveau 4
A29: 0.2 | B29: C06 : VALIDER UN SYSTÈME INFORMATIQUE | C29: Non réalisé | D29: Réalisation partielle | E29: Réalisation satisfaisante | F29: Réalisation très satisfaisante
A30: =SUM(A31:A37) | B30: Critères d’évaluation de la compétence | C30: 0 observable | D30: 1 observable | E30: 2 à 3 observables | F30: 4 observables
A31: 0.2 | B31: Les exigences à valider sont identifiées dans le périmètre défini | G31: =IF(C31="x",0,IF(D31="x",1,IF(E31="x",2,IF(F31="x",3,IF(TRUE,""))))) | H31: =COUNTBLANK(C31:F31) | I31: =IF(H31=3,"",IF(H31<>3,"EVALUATION DE CE CRITERE A REVOIR"))
A32: 0.2 | B32: Les procédures de test sont établies | G32: =IF(C32="x",0,IF(D32="x",1,IF(E32="x",2,IF(F32="x",3,IF(TRUE,""))))) | H32: =COUNTBLANK(C32:F32) | I32: =IF(H32=3,"",IF(H32<>3,"EVALUATION DE CE CRITERE A REVOIR"))
A33: 0.1 | B33: Les tests (unitaires, d’intégration et autres) sont appliqués | G33: =IF(C33="x",0,IF(D33="x",1,IF(E33="x",2,IF(F33="x",3,IF(TRUE,""))))) | H33: =COUNTBLANK(C33:F33) | I33: =IF(H33=3,"",IF(H33<>3,"EVALUATION DE CE CRITERE A REVOIR"))
A34: 0.1 | B34: Les résultats de tests sont synthétisés pour évaluer la conformité globale | G34: =IF(C34="x",0,IF(D34="x",1,IF(E34="x",2,IF(F34="x",3,IF(TRUE,""))))) | H34: =COUNTBLANK(C34:F34) | I34: =IF(H34=3,"",IF(H34<>3,"EVALUATION DE CE CRITERE A REVOIR"))
A35: 0.1 | B35: Le document de recette est validé par le client et la recette est réalisée avec le client | G35: =IF(C35="x",0,IF(D35="x",1,IF(E35="x",2,IF(F35="x",3,IF(TRUE,""))))) | H35: =COUNTBLANK(C35:F35) | I35: =IF(H35=3,"",IF(H35<>3,"EVALUATION DE CE CRITERE A REVOIR"))
A37: 0.3 | B37: - Le travail est préparé de façon à satisfaire les exigences de qualité, d’efficacité et d’échéancier - Le calme est conservé de façon constante dans des situations particulières, tout en persévérant dans la tâche jusqu’à l’atteinte du résultat sans se décourager - Face à un ensemble de faits, des actions appropriées à poser sont décidées | G37: =IF(C37="x",0,IF(D37="x",1,IF(E37="x",2,IF(F37="x",3,IF(TRUE,""))))) | H37: =COUNTBLANK(C37:F37) | I37: =IF(H37=3,"",IF(H37<>3,"EVALUATION DE CE CRITERE A REVOIR"))
E38: Total | F38: =SUMPRODUCT(A31:A37,G31:G37)
E39: Curseur | F39: =MAX(F38,'E5-FICHE SEMESTRE2 E5-IR'!F39*2/3)
C40: Positionner le niveau de maitrise
C41: Niveau 1 | D41: Niveau 2 | E41: Niveau 3 | F41: Niveau 4
A42: 0.3 | B42: C09 : INSTALLER UN RÉSEAU INFORMATIQUE | C42: Non réalisé | D42: Réalisation partielle | E42: Réalisation satisfaisante | F42: Réalisation très satisfaisante
A43: =SUM(A44:A50) | B43: Critères d’évaluation de la compétence | C43: 0 observable | D43: 1 observable | E43: 2 à 3 observables | F43: 4 observables
A44: 0.2 | B44: Les équipements nécessaires à la réponse au CDC (fourni par le client) sont identifiés | G44: =IF(C44="x",0,IF(D44="x",1,IF(E44="x",2,IF(F44="x",3,IF(TRUE,""))))) | H44: =COUNTBLANK(C44:F44) | I44: =IF(H44=3,"",IF(H44<>3,"EVALUATION DE CE CRITERE A REVOIR"))
A45: 0.2 | B45: Une procédure de configuration ou d’installation est déterminée ainsi que les points critiques, les procédures étant soumises à validation si nécessaire | G45: =IF(C45="x",0,IF(D45="x",1,IF(E45="x",2,IF(F45="x",3,IF(TRUE,""))))) | H45: =COUNTBLANK(C45:F45) | I45: =IF(H45=3,"",IF(H45<>3,"EVALUATION DE CE CRITERE A REVOIR"))
A46: 0.1 | B46: La ou les procédures choisies sont suivies | G46: =IF(C46="x",0,IF(D46="x",1,IF(E46="x",2,IF(F46="x",3,IF(TRUE,""))))) | H46: =COUNTBLANK(C46:F46) | I46: =IF(H46=3,"",IF(H46<>3,"EVALUATION DE CE CRITERE A REVOIR"))
A47: 0.1 | B47: Les activités sont menées en respectant les règles de sécurité | G47: =IF(C47="x",0,IF(D47="x",1,IF(E47="x",2,IF(F47="x",3,IF(TRUE,""))))) | H47: =COUNTBLANK(C47:F47) | I47: =IF(H47=3,"",IF(H47<>3,"EVALUATION DE CE CRITERE A REVOIR"))
...

Sheet E5-FICHE SEMESTRE4 E5-IR
A1: BREVET DE TECHNICIEN SUPERIEUR CYBERSECURITE, INFORMATIQUE et RESEAUX, ELECTRONIQUE
A3: Épreuve E5 : Exploitation et maintenance de réseaux informatiques
A5: SESSION 2027
A7: Commentaire (obligatoire si note finale inférieure à 10/20) | C7: Académie : | E7: Académie de Versailles
C8: Établissement : | E8: Lycée Isaac Newton
C9: Nom : | E9: ABAID
C10: Prénom : | E10: Soulaimane
C11: Numéro du candidat : | E11: 2025001
C12: Date :
A14: GRILLE D'ÉVALUATION
C16: Positionner le niveau de maitrise
C17: Niveau 1 | D17: Niveau 2 | E17: Niveau 3 | F17: Niveau 4
A18: 0.2 | B18: C02 : ORGANISER UNE INTERVENTION | C18: Non réalisé | D18: Réalisation partielle | E18: Réalisation satisfaisante | F18: Réalisation très satisfaisante
A19: =SUM(A20:A24) | B19: Critères d’évaluation de la compétence | C19: 0 observable | D19: 1 observable | E19: 2 à 3 observables | F19: 4 observables
A20: 0.25 | B20: Les différents interlocuteurs et ressources sont identifiés | G20: =IF(C20="x",0,IF(D20="x",1,IF(E20="x",2,IF(F20="x",3,IF(TRUE,""))))) | H20: =COUNTBLANK(C20:F20) | I20: =IF(H20=3,"",IF(H20<>3,"EVALUATION DE CE CRITERE A REVOIR"))
A21: 0.25 | B21: Le cahier des charges préliminaire est complété et les ressources permettant de répondre au cahier des charges sont décrites | G21: =IF(C21="x",0,IF(D21="x",1,IF(E21="x",2,IF(F21="x",3,IF(TRUE,""))))) | H21: =COUNTBLANK(C21:F21) | I21: =IF(H21=3,"",IF(H21<>3,"EVALUATION DE CE CRITERE A REVOIR"))
A22: 0.2 | B22: Le planning prévisionnel est interprété | G22: =IF(C22="x",0,IF(D22="x",1,IF(E22="x",2,IF(F22="x",3,IF(TRUE,""))))) | H22: =COUNTBLANK(C22:F22) | I22: =IF(H22=3,"",IF(H22<>3,"EVALUATION DE CE CRITERE A REVOIR"))
A24: 0.3 | B24: - Face à un ensemble de faits, des actions appropriées à poser sont décidées - De façon à poser des actions au moment opportun dans un contexte déterminé, la prise en charge est adaptée selon les responsabilités - Le travail est préparé de façon à satisfaire les exigences de qualité, d’efficacité et d’échéancier | G24: =IF(C24="x",0,IF(D24="x",1,IF(E24="x",2,IF(F24="x",3,IF(TRUE,""))))) | H24: =COUNTBLANK(C24:F24) | I24: =IF(H24=3,"",IF(H24<>3,"EVALUATION DE CE CRITERE A REVOIR"))
E25: Total | F25: =SUMPRODUCT(A20:A24,G20:G24)
E26: Curseur | F26: =MAX(F25,'E5-FICHE SEMESTRE3 E5-IR'!F26)
C27: Positionner le niveau de maitrise
C28: Niveau 1 | D28: Niveau 2 | E28: Niveau 3 | F28: Niveau 4
A29: 0.2 | B29: C06 : VALIDER UN SYSTÈME INFORMATIQUE | C29: Non réalisé | D29: Réalisation partielle | E29: Réalisation satisfaisante | F29: Réalisation très satisfaisante
A30: =SUM(A31:A37) | B30: Critères d’évaluation de la compétence | C30: 0 observable | D30: 1 observable | E30: 2 à 3 observables | F30: 4 observables
A31: 0.2 | B31: Les exigences à valider sont identifiées dans le périmètre défini | G31: =IF(C31="x",0,IF(D31="x",1,IF(E31="x",2,IF(F31="x",3,IF(TRUE,""))))) | H31: =COUNTBLANK(C31:F31) | I31: =IF(H31=3,"",IF(H31<>3,"EVALUATION DE CE CRITERE A REVOIR"))
A32: 0.2 | B32: Les procédures de test sont établies | G32: =IF(C32="x",0,IF(D32="x",1,IF(E32="x",2,IF(F32="x",3,IF(TRUE,""))))) | H32: =COUNTBLANK(C32:F32) | I32: =IF(H32=3,"",IF(H32<>3,"EVALUATION DE CE CRITERE A REVOIR"))
A33: 0.1 | B33: Les tests (unitaires, d’intégration et autres) sont appliqués | G33: =IF(C33="x",0,IF(D33="x",1,IF(E33="x",2,IF(F33="x",3,IF(TRUE,""))))) | H33: =COUNTBLANK(C33:F33) | I33: =IF(H33=3,"",IF(H33<>3,"EVALUATION DE CE CRITERE A REVOIR"))
A34: 0.1 | B34: Les résultats de tests sont synthétisés pour évaluer la conformité globale | G34: =IF(C34="x",0,IF(D34="x",1,IF(E34="x",2,IF(F34="x",3,IF(TRUE,""))))) | H34: =COUNTBLANK(C34:F34) | I34: =IF(H34=3,"",IF(H34<>3,"EVALUATION DE CE CRITERE A REVOIR"))
A35: 0.1 | B35: Le document de recette est validé par le client et la recette est réalisée avec le client | G35: =IF(C35="x",0,IF(D35="x",1,IF(E35="x",2,IF(F35="x",3,IF(TRUE,""))))) | H35: =COUNTBLANK(C35:F35) | I35: =IF(H35=3,"",IF(H35<>3,"EVALUATION DE CE CRITERE A REVOIR"))
A37: 0.3 | B37: - Le travail est préparé de façon à satisfaire les exigences de qualité, d’efficacité et d’échéancier - Le calme est conservé de façon constante dans des situations particulières, tout en persévérant dans la tâche jusqu’à l’atteinte du résultat sans se décourager - Face à un ensemble de faits, des actions appropriées à poser sont décidées | G37: =IF(C37="x",0,IF(D37="x",1,IF(E37="x",2,IF(F37="x",3,IF(TRUE,""))))) | H37: =COUNTBLANK(C37:F37) | I37: =IF(H37=3,"",IF(H37<>3,"EVALUATION DE CE CRITERE A REVOIR"))
E38: Total | F38: =SUMPRODUCT(A31:A37,G31:G37)
E39: Curseur | F39: =MAX(F38,'E5-FICHE SEMESTRE3 E5-IR'!F39)
C40: Positionner le niveau de maitrise
C41: Niveau 1 | D41: Niveau 2 | E41: Niveau 3 | F41: Niveau 4
A42: 0.3 | B42: C09 : INSTALLER UN RÉSEAU INFORMATIQUE | C42: Non réalisé | D42: Réalisation partielle | E42: Réalisation satisfaisante | F42: Réalisation très satisfaisante
A43: =SUM(A44:A50) | B43: Critères d’évaluation de la compétence | C43: 0 observable | D43: 1 observable | E43: 2 à 3 observables | F43: 4 observables
A44: 0.2 | B44: Les équipements nécessaires à la réponse au CDC (fourni par le client) sont identifiés | G44: =IF(C44="x",0,IF(D44="x",1,IF(E44="x",2,IF(F44="x",3,IF(TRUE,""))))) | H44: =COUNTBLANK(C44:F44) | I44: =IF(H44=3,"",IF(H44<>3,"EVALUATION DE CE CRITERE A REVOIR"))
A45: 0.2 | B45: Une procédure de configuration ou d’installation est déterminée ainsi que les points critiques, les procédures étant soumises à validation si nécessaire | G45: =IF(C45="x",0,IF(D45="x",1,IF(E45="x",2,IF(F45="x",3,IF(TRUE,""))))) | H45: =COUNTBLANK(C45:F45) | I45: =IF(H45=3,"",IF(H45<>3,"EVALUATION DE CE CRITERE A REVOIR"))
A46: 0.1 | B46: La ou les procédures choisies sont suivies | G46: =IF(C46="x",0,IF(D46="x",1,IF(E46="x",2,IF(F46="x",3,IF(TRUE,""))))) | H46: =COUNTBLANK(C46:F46) | I46: =IF(H46=3,"",IF(H46<>3,"EVALUATION DE CE CRITERE A REVOIR"))
A47: 0.1 | B47: Les activités sont menées en respectant les règles de sécurité | G47: =IF(C47="x",0,IF(D47="x",1,IF(E47="x",2,IF(F47="x",3,IF(TRUE,""))))) | H47: =COUNTBLANK(C47:F47) | I47: =IF(H47=3,"",IF(H47<>3,"EVALUATION DE CE CRITERE A REVOIR"))
...

Sheet E5-FICHE RECAPITULATIVE E5-IR
A1: BREVET DE TECHNICIEN SUPERIEUR CYBERSECURITE, INFORMATIQUE et RESEAUX, ELECTRONIQUE
A3: Épreuve E5 : Exploitation et maintenance de réseaux informatiques
A5: SESSION 2027
A7: Commentaire (obligatoire si note finale inférieure à 10/20) | C7: Académie : | E7: Académie de Versailles
C8: Établissement : | E8: Lycée Isaac Newton
C9: Nom : | E9: ABAID
C10: Prénom : | E10: Soulaimane
C11: Numéro du candidat : | E11: 2025001
C12: Date :
A14: GRILLE D'ÉVALUATION
C16: Positionner le niveau de maitrise
C17: Niveau 1 | D17: Niveau 2 | E17: Niveau 3 | F17: Niveau 4
A18: 0.2 | B18: C02 : ORGANISER UNE INTERVENTION | C18: Non réalisé | D18: Réalisation partielle | E18: Réalisation satisfaisante | F18: Réalisation très satisfaisante
E19: Total | F19: ='E5-FICHE SEMESTRE4 E5-IR'!F26
C21: Positionner le niveau de maitrise
C22: Niveau 1 | D22: Niveau 2 | E22: Niveau 3 | F22: Niveau 4
A23: 0.2 | B23: C06 : VALIDER UN SYSTÈME INFORMATIQUE | C23: Non réalisé | D23: Réalisation partielle | E23: Réalisation satisfaisante | F23: Réalisation très satisfaisante
E24: Total | F24: ='E5-FICHE SEMESTRE4 E5-IR'!F39
C26: Positionner le niveau de maitrise
C27: Niveau 1 | D27: Niveau 2 | E27: Niveau 3 | F27: Niveau 4
A28: 0.3 | B28: C09 : INSTALLER UN RÉSEAU INFORMATIQUE | C28: Non réalisé | D28: Réalisation partielle | E28: Réalisation satisfaisante | F28: Réalisation très satisfaisante
E29: Total | F29: ='E5-FICHE SEMESTRE4 E5-IR'!F52
C31: Positionner le niveau de maitrise
C32: Niveau 1 | D32: Niveau 2 | E32: Niveau 3 | F32: Niveau 4
A33: 0.3 | B33: C11 : MAINTENIR UN RÉSEAU INFORMATIQUE | C33: Non réalisé | D33: Réalisation partielle | E33: Réalisation satisfaisante | F33: Réalisation très satisfaisante
E34: Total | F34: ='E5-FICHE SEMESTRE4 E5-IR'!F64
B36: points bonus | D36: /2
A37: Note proposée au jury de délibération | D37: /20 | E37: Note calculée | F37: =(F19*A18+F24*A23+F29*A28+F34*A33)*20/3+C36

Sheet Attendus imprimables E5 - IR

Sheet FICHE RENDU JURY E5 - ER
B15: BREVET DE TECHNICIEN SUPERIEUR CYBERSECURITE, INFORMATIQUE et RESEAUX, ELECTRONIQUE
B17: Épreuve E5 : Mise en oeuvre de réseaux informatiques
B18: SESSION 2027
B20: Académie : | C20: Académie de Versailles
B21: Établissement : | C21: Lycée Isaac Newton
B22: Nom : | C22: ABAID
B23: Prénom : | C23: Soulaimane
B24: Numéro du candidat : | C24: 2025001
B25: Date :
B28: Note proposée au jury de délibération | C28: … | D28: /20
B30: Commentaires destinés à éclairer le jury:
B33: Prénom et nom et qualité des membres de la commission :
